2019-06-25 14:20:31 - INFO - werkzeug[line:87]:  * Running on http://0.0.0.0:8000/ (Press CTRL+C to quit)
2019-06-25 14:20:50 - INFO - werkzeug[line:87]: 127.0.0.1 - - [25/Jun/2019 14:20:50] "[33mGET / HTTP/1.1[0m" 404 -
2019-06-25 14:20:51 - INFO - werkzeug[line:87]: 127.0.0.1 - - [25/Jun/2019 14:20:51] "[33mGET /favicon.ico HTTP/1.1[0m" 404 -
2019-06-25 16:54:20 - ERROR - bin.app[line:75]: Expecting value: line 1 column 1 (char 0)
Traceback (most recent call last):
  File "/Users/apple/Desktop/pollution_statistic_forecast_app-develop_lstm/bin/app.py", line 66, in correlation
    data = json.loads(request.data)
  File "/Users/apple/anaconda3/lib/python3.6/json/__init__.py", line 354, in loads
    return _default_decoder.decode(s)
  File "/Users/apple/anaconda3/lib/python3.6/json/decoder.py", line 339, in decode
    obj, end = self.raw_decode(s, idx=_w(s, 0).end())
  File "/Users/apple/anaconda3/lib/python3.6/json/decoder.py", line 357, in raw_decode
    raise JSONDecodeError("Expecting value", s, err.value) from None
json.decoder.JSONDecodeError: Expecting value: line 1 column 1 (char 0)
2019-06-25 16:55:04 - ERROR - bin.app[line:75]: Expecting value: line 1 column 1 (char 0)
Traceback (most recent call last):
  File "/Users/apple/Desktop/pollution_statistic_forecast_app-develop_lstm/bin/app.py", line 66, in correlation
    data = json.loads(request.data)
  File "/Users/apple/anaconda3/lib/python3.6/json/__init__.py", line 354, in loads
    return _default_decoder.decode(s)
  File "/Users/apple/anaconda3/lib/python3.6/json/decoder.py", line 339, in decode
    obj, end = self.raw_decode(s, idx=_w(s, 0).end())
  File "/Users/apple/anaconda3/lib/python3.6/json/decoder.py", line 357, in raw_decode
    raise JSONDecodeError("Expecting value", s, err.value) from None
json.decoder.JSONDecodeError: Expecting value: line 1 column 1 (char 0)
2019-06-25 16:57:53 - ERROR - bin.app[line:75]: Expecting value: line 1 column 1 (char 0)
Traceback (most recent call last):
  File "/Users/apple/Desktop/pollution_statistic_forecast_app-develop_lstm/bin/app.py", line 66, in correlation
    data = json.loads(request.data)
  File "/Users/apple/anaconda3/lib/python3.6/json/__init__.py", line 354, in loads
    return _default_decoder.decode(s)
  File "/Users/apple/anaconda3/lib/python3.6/json/decoder.py", line 339, in decode
    obj, end = self.raw_decode(s, idx=_w(s, 0).end())
  File "/Users/apple/anaconda3/lib/python3.6/json/decoder.py", line 357, in raw_decode
    raise JSONDecodeError("Expecting value", s, err.value) from None
json.decoder.JSONDecodeError: Expecting value: line 1 column 1 (char 0)
2019-06-25 17:07:54 - ERROR - bin.app[line:75]: Expecting value: line 1 column 1 (char 0)
Traceback (most recent call last):
  File "/Users/apple/Desktop/pollution_statistic_forecast_app-develop_lstm/bin/app.py", line 66, in correlation
    data = json.loads(request.data)
  File "/Users/apple/anaconda3/lib/python3.6/json/__init__.py", line 354, in loads
    return _default_decoder.decode(s)
  File "/Users/apple/anaconda3/lib/python3.6/json/decoder.py", line 339, in decode
    obj, end = self.raw_decode(s, idx=_w(s, 0).end())
  File "/Users/apple/anaconda3/lib/python3.6/json/decoder.py", line 357, in raw_decode
    raise JSONDecodeError("Expecting value", s, err.value) from None
json.decoder.JSONDecodeError: Expecting value: line 1 column 1 (char 0)
2019-06-25 17:09:33 - INFO - werkzeug[line:87]:  * Running on http://0.0.0.0:8000/ (Press CTRL+C to quit)
2019-06-25 17:10:06 - ERROR - bin.app[line:76]: 'bytes' object has no attribute 'copy'
Traceback (most recent call last):
  File "/Users/apple/Desktop/pollution_statistic_forecast_app-develop_lstm/bin/app.py", line 68, in correlation
    data = time_delayed_correlation_analysis.get_normalized_samples(data)
  File "/Users/apple/Desktop/pollution_statistic_forecast_app-develop_lstm/mods/time_delayed_correlation_analysis.py", line 18, in get_normalized_samples
    data = data.copy()
AttributeError: 'bytes' object has no attribute 'copy'
2019-06-25 17:10:57 - ERROR - bin.app[line:77]: 'bytes' object has no attribute 'copy'
Traceback (most recent call last):
  File "/Users/apple/Desktop/pollution_statistic_forecast_app-develop_lstm/bin/app.py", line 69, in correlation
    data = time_delayed_correlation_analysis.get_normalized_samples(data)
  File "/Users/apple/Desktop/pollution_statistic_forecast_app-develop_lstm/mods/time_delayed_correlation_analysis.py", line 18, in get_normalized_samples
    data = data.copy()
AttributeError: 'bytes' object has no attribute 'copy'
2019-06-25 17:13:34 - ERROR - bin.app[line:79]: 'bytes' object has no attribute 'copy'
Traceback (most recent call last):
  File "/Users/apple/Desktop/pollution_statistic_forecast_app-develop_lstm/bin/app.py", line 71, in correlation
    data = time_delayed_correlation_analysis.get_normalized_samples(data)
  File "/Users/apple/Desktop/pollution_statistic_forecast_app-develop_lstm/mods/time_delayed_correlation_analysis.py", line 18, in get_normalized_samples
    data = data.copy()
AttributeError: 'bytes' object has no attribute 'copy'
2019-06-25 17:14:23 - ERROR - bin.app[line:79]: Expecting value: line 1 column 1 (char 0)
Traceback (most recent call last):
  File "/Users/apple/Desktop/pollution_statistic_forecast_app-develop_lstm/bin/app.py", line 69, in correlation
    data = json.loads(request.data)
  File "/Users/apple/anaconda3/lib/python3.6/json/__init__.py", line 354, in loads
    return _default_decoder.decode(s)
  File "/Users/apple/anaconda3/lib/python3.6/json/decoder.py", line 339, in decode
    obj, end = self.raw_decode(s, idx=_w(s, 0).end())
  File "/Users/apple/anaconda3/lib/python3.6/json/decoder.py", line 357, in raw_decode
    raise JSONDecodeError("Expecting value", s, err.value) from None
json.decoder.JSONDecodeError: Expecting value: line 1 column 1 (char 0)
2019-06-25 17:24:50 - ERROR - bin.app[line:78]: Expecting value: line 1 column 1 (char 0)
Traceback (most recent call last):
  File "/Users/apple/Desktop/pollution_statistic_forecast_app-develop_lstm/bin/app.py", line 68, in correlation
    data = json.loads(request.data)
  File "/Users/apple/anaconda3/lib/python3.6/json/__init__.py", line 354, in loads
    return _default_decoder.decode(s)
  File "/Users/apple/anaconda3/lib/python3.6/json/decoder.py", line 339, in decode
    obj, end = self.raw_decode(s, idx=_w(s, 0).end())
  File "/Users/apple/anaconda3/lib/python3.6/json/decoder.py", line 357, in raw_decode
    raise JSONDecodeError("Expecting value", s, err.value) from None
json.decoder.JSONDecodeError: Expecting value: line 1 column 1 (char 0)
2019-06-25 17:25:17 - INFO - werkzeug[line:87]:  * Running on http://0.0.0.0:8000/ (Press CTRL+C to quit)
2019-06-25 17:25:38 - ERROR - bin.app[line:78]: Expecting value: line 1 column 1 (char 0)
Traceback (most recent call last):
  File "/Users/apple/Desktop/pollution_statistic_forecast_app-develop_lstm/bin/app.py", line 68, in correlation
    data = json.loads(request.data)
  File "/Users/apple/anaconda3/lib/python3.6/json/__init__.py", line 354, in loads
    return _default_decoder.decode(s)
  File "/Users/apple/anaconda3/lib/python3.6/json/decoder.py", line 339, in decode
    obj, end = self.raw_decode(s, idx=_w(s, 0).end())
  File "/Users/apple/anaconda3/lib/python3.6/json/decoder.py", line 357, in raw_decode
    raise JSONDecodeError("Expecting value", s, err.value) from None
json.decoder.JSONDecodeError: Expecting value: line 1 column 1 (char 0)
2019-06-25 17:34:26 - ERROR - bin.app[line:47]: 'dict' object has no attribute 'drop'
Traceback (most recent call last):
  File "/Users/luolei/Documents/Git_Repository_Dreisteine/chrissun99_pollution_forcast/bin/app.py", line 39, in correlation
    data = time_delayed_correlation_analysis.get_normalized_samples(data)
  File "/Users/luolei/Documents/Git_Repository_Dreisteine/chrissun99_pollution_forcast/mods/time_delayed_correlation_analysis.py", line 19, in get_normalized_samples
    data.drop(['ptime', 'time_stamp'], axis = 1, inplace = True)
AttributeError: 'dict' object has no attribute 'drop'
2019-06-25 17:40:47 - ERROR - bin.app[line:46]: 'dict' object has no attribute 'drop'
Traceback (most recent call last):
  File "/Users/luolei/Documents/Git_Repository_Dreisteine/chrissun99_pollution_forcast/bin/app.py", line 38, in correlation
    data = time_delayed_correlation_analysis.get_normalized_samples(data)
  File "/Users/luolei/Documents/Git_Repository_Dreisteine/chrissun99_pollution_forcast/mods/time_delayed_correlation_analysis.py", line 19, in get_normalized_samples
    data.drop(['ptime', 'time_stamp'], axis = 1, inplace = True)
AttributeError: 'dict' object has no attribute 'drop'
2019-06-25 17:43:58 - ERROR - bin.app[line:46]: 'dict' object has no attribute 'drop'
Traceback (most recent call last):
  File "/Users/luolei/Documents/Git_Repository_Dreisteine/chrissun99_pollution_forcast/bin/app.py", line 38, in correlation
    data = time_delayed_correlation_analysis.get_normalized_samples(data)
  File "/Users/luolei/Documents/Git_Repository_Dreisteine/chrissun99_pollution_forcast/mods/time_delayed_correlation_analysis.py", line 19, in get_normalized_samples
    data.drop(['ptime', 'time_stamp'], axis = 1, inplace = True)
AttributeError: 'dict' object has no attribute 'drop'
2019-06-25 17:45:22 - ERROR - bin.app[line:47]: 'dict' object has no attribute 'drop'
Traceback (most recent call last):
  File "/Users/luolei/Documents/Git_Repository_Dreisteine/chrissun99_pollution_forcast/bin/app.py", line 39, in correlation
    data = time_delayed_correlation_analysis.get_normalized_samples(data)
  File "/Users/luolei/Documents/Git_Repository_Dreisteine/chrissun99_pollution_forcast/mods/time_delayed_correlation_analysis.py", line 19, in get_normalized_samples
    data.drop(['ptime', 'time_stamp'], axis = 1, inplace = True)
AttributeError: 'dict' object has no attribute 'drop'
2019-06-25 17:45:54 - ERROR - bin.app[line:47]: 'dict' object has no attribute 'drop'
Traceback (most recent call last):
  File "/Users/luolei/Documents/Git_Repository_Dreisteine/chrissun99_pollution_forcast/bin/app.py", line 39, in correlation
    data = time_delayed_correlation_analysis.get_normalized_samples(data)
  File "/Users/luolei/Documents/Git_Repository_Dreisteine/chrissun99_pollution_forcast/mods/time_delayed_correlation_analysis.py", line 19, in get_normalized_samples
    data.drop(['ptime', 'time_stamp'], axis = 1, inplace = True)
AttributeError: 'dict' object has no attribute 'drop'
2019-06-25 17:46:22 - ERROR - bin.app[line:47]: 'dict' object has no attribute 'drop'
Traceback (most recent call last):
  File "/Users/luolei/Documents/Git_Repository_Dreisteine/chrissun99_pollution_forcast/bin/app.py", line 39, in correlation
    data = time_delayed_correlation_analysis.get_normalized_samples(data)
  File "/Users/luolei/Documents/Git_Repository_Dreisteine/chrissun99_pollution_forcast/mods/time_delayed_correlation_analysis.py", line 19, in get_normalized_samples
    data.drop(['ptime', 'time_stamp'], axis = 1, inplace = True)
AttributeError: 'dict' object has no attribute 'drop'
2019-06-25 17:47:54 - ERROR - bin.app[line:47]: 'list' object has no attribute 'drop'
Traceback (most recent call last):
  File "/Users/luolei/Documents/Git_Repository_Dreisteine/chrissun99_pollution_forcast/bin/app.py", line 39, in correlation
    data = get_normalized_samples(data['data'])
  File "/Users/luolei/Documents/Git_Repository_Dreisteine/chrissun99_pollution_forcast/mods/time_delayed_correlation_analysis.py", line 19, in get_normalized_samples
    data.drop(['ptime', 'time_stamp'], axis = 1, inplace = True)
AttributeError: 'list' object has no attribute 'drop'
2019-06-25 17:53:20 - ERROR - bin.app[line:47]: Expecting value: line 1 column 1 (char 0)
Traceback (most recent call last):
  File "/Users/apple/Desktop/pollution_statistic_forecast_app-develop_lstm/bin/app.py", line 37, in correlation
    data = json.loads(request.data)['data']
  File "/Users/apple/anaconda3/lib/python3.6/json/__init__.py", line 354, in loads
    return _default_decoder.decode(s)
  File "/Users/apple/anaconda3/lib/python3.6/json/decoder.py", line 339, in decode
    obj, end = self.raw_decode(s, idx=_w(s, 0).end())
  File "/Users/apple/anaconda3/lib/python3.6/json/decoder.py", line 357, in raw_decode
    raise JSONDecodeError("Expecting value", s, err.value) from None
json.decoder.JSONDecodeError: Expecting value: line 1 column 1 (char 0)
2019-06-25 17:53:38 - INFO - werkzeug[line:87]:  * Running on http://0.0.0.0:8000/ (Press CTRL+C to quit)
2019-06-25 17:54:55 - ERROR - bin.app[line:46]: Expecting value: line 1 column 1 (char 0)
Traceback (most recent call last):
  File "/Users/apple/Desktop/pollution_statistic_forecast_app-develop_lstm/bin/app.py", line 36, in correlation
    data = json.loads(request.data)['data']
  File "/Users/apple/anaconda3/lib/python3.6/json/__init__.py", line 354, in loads
    return _default_decoder.decode(s)
  File "/Users/apple/anaconda3/lib/python3.6/json/decoder.py", line 339, in decode
    obj, end = self.raw_decode(s, idx=_w(s, 0).end())
  File "/Users/apple/anaconda3/lib/python3.6/json/decoder.py", line 357, in raw_decode
    raise JSONDecodeError("Expecting value", s, err.value) from None
json.decoder.JSONDecodeError: Expecting value: line 1 column 1 (char 0)
2019-06-25 18:05:05 - INFO - werkzeug[line:87]:  * Running on http://0.0.0.0:8000/ (Press CTRL+C to quit)
2019-06-25 18:05:11 - INFO - werkzeug[line:87]:  * Running on http://0.0.0.0:8000/ (Press CTRL+C to quit)
2019-06-25 18:05:32 - ERROR - bin.app[line:46]: Expecting value: line 1 column 1 (char 0)
Traceback (most recent call last):
  File "/Users/apple/Desktop/pollution_statistic_forecast_app-develop_lstm/bin/app.py", line 36, in correlation
    data = json.loads(request.data)['data']
  File "/Users/apple/anaconda3/lib/python3.6/json/__init__.py", line 354, in loads
    return _default_decoder.decode(s)
  File "/Users/apple/anaconda3/lib/python3.6/json/decoder.py", line 339, in decode
    obj, end = self.raw_decode(s, idx=_w(s, 0).end())
  File "/Users/apple/anaconda3/lib/python3.6/json/decoder.py", line 357, in raw_decode
    raise JSONDecodeError("Expecting value", s, err.value) from None
json.decoder.JSONDecodeError: Expecting value: line 1 column 1 (char 0)
2019-06-25 18:16:17 - ERROR - bin.app[line:47]: Expecting value: line 1 column 1 (char 0)
Traceback (most recent call last):
  File "/Users/apple/Desktop/pollution_statistic_forecast_app-develop_lstm/bin/app.py", line 37, in correlation
    data = json.loads(request.data)['data']
  File "/Users/apple/anaconda3/lib/python3.6/json/__init__.py", line 354, in loads
    return _default_decoder.decode(s)
  File "/Users/apple/anaconda3/lib/python3.6/json/decoder.py", line 339, in decode
    obj, end = self.raw_decode(s, idx=_w(s, 0).end())
  File "/Users/apple/anaconda3/lib/python3.6/json/decoder.py", line 357, in raw_decode
    raise JSONDecodeError("Expecting value", s, err.value) from None
json.decoder.JSONDecodeError: Expecting value: line 1 column 1 (char 0)
2019-06-25 18:21:35 - ERROR - bin.app[line:47]: Expecting value: line 1 column 1 (char 0)
Traceback (most recent call last):
  File "/Users/apple/Desktop/pollution_statistic_forecast_app-develop_lstm/bin/app.py", line 37, in correlation
    data = json.loads(request.data)
  File "/Users/apple/anaconda3/lib/python3.6/json/__init__.py", line 354, in loads
    return _default_decoder.decode(s)
  File "/Users/apple/anaconda3/lib/python3.6/json/decoder.py", line 339, in decode
    obj, end = self.raw_decode(s, idx=_w(s, 0).end())
  File "/Users/apple/anaconda3/lib/python3.6/json/decoder.py", line 357, in raw_decode
    raise JSONDecodeError("Expecting value", s, err.value) from None
json.decoder.JSONDecodeError: Expecting value: line 1 column 1 (char 0)
2019-06-25 18:22:04 - ERROR - bin.app[line:47]: Expecting value: line 1 column 1 (char 0)
Traceback (most recent call last):
  File "/Users/apple/Desktop/pollution_statistic_forecast_app-develop_lstm/bin/app.py", line 37, in correlation
    data = json.loads(request.data)
  File "/Users/apple/anaconda3/lib/python3.6/json/__init__.py", line 354, in loads
    return _default_decoder.decode(s)
  File "/Users/apple/anaconda3/lib/python3.6/json/decoder.py", line 339, in decode
    obj, end = self.raw_decode(s, idx=_w(s, 0).end())
  File "/Users/apple/anaconda3/lib/python3.6/json/decoder.py", line 357, in raw_decode
    raise JSONDecodeError("Expecting value", s, err.value) from None
json.decoder.JSONDecodeError: Expecting value: line 1 column 1 (char 0)
2019-06-25 18:24:49 - ERROR - bin.app[line:46]: Expecting value: line 1 column 1 (char 0)
Traceback (most recent call last):
  File "/Users/apple/Desktop/pollution_statistic_forecast_app-develop_lstm/bin/app.py", line 36, in correlation
    data = json.loads(request.data)
  File "/Users/apple/anaconda3/lib/python3.6/json/__init__.py", line 354, in loads
    return _default_decoder.decode(s)
  File "/Users/apple/anaconda3/lib/python3.6/json/decoder.py", line 339, in decode
    obj, end = self.raw_decode(s, idx=_w(s, 0).end())
  File "/Users/apple/anaconda3/lib/python3.6/json/decoder.py", line 357, in raw_decode
    raise JSONDecodeError("Expecting value", s, err.value) from None
json.decoder.JSONDecodeError: Expecting value: line 1 column 1 (char 0)
2019-06-25 18:25:39 - ERROR - bin.app[line:47]: Expecting value: line 1 column 1 (char 0)
Traceback (most recent call last):
  File "/Users/apple/Desktop/pollution_statistic_forecast_app-develop_lstm/bin/app.py", line 37, in correlation
    data = json.loads(request.data)
  File "/Users/apple/anaconda3/lib/python3.6/json/__init__.py", line 354, in loads
    return _default_decoder.decode(s)
  File "/Users/apple/anaconda3/lib/python3.6/json/decoder.py", line 339, in decode
    obj, end = self.raw_decode(s, idx=_w(s, 0).end())
  File "/Users/apple/anaconda3/lib/python3.6/json/decoder.py", line 357, in raw_decode
    raise JSONDecodeError("Expecting value", s, err.value) from None
json.decoder.JSONDecodeError: Expecting value: line 1 column 1 (char 0)
2019-06-25 18:26:32 - ERROR - bin.app[line:47]: Expecting value: line 1 column 1 (char 0)
Traceback (most recent call last):
  File "/Users/apple/Desktop/pollution_statistic_forecast_app-develop_lstm/bin/app.py", line 37, in correlation
    data = json.loads(request.data)
  File "/Users/apple/anaconda3/lib/python3.6/json/__init__.py", line 354, in loads
    return _default_decoder.decode(s)
  File "/Users/apple/anaconda3/lib/python3.6/json/decoder.py", line 339, in decode
    obj, end = self.raw_decode(s, idx=_w(s, 0).end())
  File "/Users/apple/anaconda3/lib/python3.6/json/decoder.py", line 357, in raw_decode
    raise JSONDecodeError("Expecting value", s, err.value) from None
json.decoder.JSONDecodeError: Expecting value: line 1 column 1 (char 0)
2019-06-25 19:15:08 - ERROR - bin.app[line:47]: Expecting value: line 1 column 1 (char 0)
Traceback (most recent call last):
  File "/Users/apple/Desktop/pollution_statistic_forecast_app-develop_lstm/bin/app.py", line 37, in correlation
    data = json.loads(request.data)
  File "/Users/apple/anaconda3/lib/python3.6/json/__init__.py", line 354, in loads
    return _default_decoder.decode(s)
  File "/Users/apple/anaconda3/lib/python3.6/json/decoder.py", line 339, in decode
    obj, end = self.raw_decode(s, idx=_w(s, 0).end())
  File "/Users/apple/anaconda3/lib/python3.6/json/decoder.py", line 357, in raw_decode
    raise JSONDecodeError("Expecting value", s, err.value) from None
json.decoder.JSONDecodeError: Expecting value: line 1 column 1 (char 0)
2019-06-25 19:23:57 - ERROR - bin.app[line:47]: Expecting value: line 1 column 1 (char 0)
Traceback (most recent call last):
  File "/Users/apple/Desktop/pollution_statistic_forecast_app-develop_lstm/bin/app.py", line 37, in correlation
    data = json.loads(request.data)
  File "/Users/apple/anaconda3/lib/python3.6/json/__init__.py", line 354, in loads
    return _default_decoder.decode(s)
  File "/Users/apple/anaconda3/lib/python3.6/json/decoder.py", line 339, in decode
    obj, end = self.raw_decode(s, idx=_w(s, 0).end())
  File "/Users/apple/anaconda3/lib/python3.6/json/decoder.py", line 357, in raw_decode
    raise JSONDecodeError("Expecting value", s, err.value) from None
json.decoder.JSONDecodeError: Expecting value: line 1 column 1 (char 0)
2019-06-25 19:27:42 - ERROR - bin.app[line:47]: byte indices must be integers or slices, not str
Traceback (most recent call last):
  File "/Users/apple/Desktop/pollution_statistic_forecast_app-develop_lstm/bin/app.py", line 37, in correlation
    data = json.loads(request.data['data'])
TypeError: byte indices must be integers or slices, not str
2019-06-25 19:32:37 - ERROR - bin.app[line:51]: No columns to parse from file
Traceback (most recent call last):
  File "/Users/apple/Desktop/pollution_statistic_forecast_app-develop_lstm/bin/app.py", line 41, in correlation
    data = pd.read_csv(data)
  File "/Users/apple/anaconda3/lib/python3.6/site-packages/pandas/io/parsers.py", line 702, in parser_f
    return _read(filepath_or_buffer, kwds)
  File "/Users/apple/anaconda3/lib/python3.6/site-packages/pandas/io/parsers.py", line 429, in _read
    parser = TextFileReader(filepath_or_buffer, **kwds)
  File "/Users/apple/anaconda3/lib/python3.6/site-packages/pandas/io/parsers.py", line 895, in __init__
    self._make_engine(self.engine)
  File "/Users/apple/anaconda3/lib/python3.6/site-packages/pandas/io/parsers.py", line 1122, in _make_engine
    self._engine = CParserWrapper(self.f, **self.options)
  File "/Users/apple/anaconda3/lib/python3.6/site-packages/pandas/io/parsers.py", line 1853, in __init__
    self._reader = parsers.TextReader(src, **kwds)
  File "pandas/_libs/parsers.pyx", line 545, in pandas._libs.parsers.TextReader.__cinit__
pandas.errors.EmptyDataError: No columns to parse from file
2019-06-25 19:41:46 - ERROR - bin.app[line:51]: No columns to parse from file
Traceback (most recent call last):
  File "/Users/apple/Desktop/pollution_statistic_forecast_app-develop_lstm/bin/app.py", line 41, in correlation
    data = pd.read_csv(data)
  File "/Users/apple/anaconda3/lib/python3.6/site-packages/pandas/io/parsers.py", line 702, in parser_f
    return _read(filepath_or_buffer, kwds)
  File "/Users/apple/anaconda3/lib/python3.6/site-packages/pandas/io/parsers.py", line 429, in _read
    parser = TextFileReader(filepath_or_buffer, **kwds)
  File "/Users/apple/anaconda3/lib/python3.6/site-packages/pandas/io/parsers.py", line 895, in __init__
    self._make_engine(self.engine)
  File "/Users/apple/anaconda3/lib/python3.6/site-packages/pandas/io/parsers.py", line 1122, in _make_engine
    self._engine = CParserWrapper(self.f, **self.options)
  File "/Users/apple/anaconda3/lib/python3.6/site-packages/pandas/io/parsers.py", line 1853, in __init__
    self._reader = parsers.TextReader(src, **kwds)
  File "pandas/_libs/parsers.pyx", line 545, in pandas._libs.parsers.TextReader.__cinit__
pandas.errors.EmptyDataError: No columns to parse from file
2019-06-25 19:43:20 - INFO - werkzeug[line:87]:  * Running on http://0.0.0.0:8000/ (Press CTRL+C to quit)
2019-06-25 19:43:50 - ERROR - bin.app[line:51]: No columns to parse from file
Traceback (most recent call last):
  File "/Users/apple/Desktop/pollution_statistic_forecast_app-develop_lstm/bin/app.py", line 41, in correlation
    data = pd.read_csv(data)
  File "/Users/apple/anaconda3/lib/python3.6/site-packages/pandas/io/parsers.py", line 702, in parser_f
    return _read(filepath_or_buffer, kwds)
  File "/Users/apple/anaconda3/lib/python3.6/site-packages/pandas/io/parsers.py", line 429, in _read
    parser = TextFileReader(filepath_or_buffer, **kwds)
  File "/Users/apple/anaconda3/lib/python3.6/site-packages/pandas/io/parsers.py", line 895, in __init__
    self._make_engine(self.engine)
  File "/Users/apple/anaconda3/lib/python3.6/site-packages/pandas/io/parsers.py", line 1122, in _make_engine
    self._engine = CParserWrapper(self.f, **self.options)
  File "/Users/apple/anaconda3/lib/python3.6/site-packages/pandas/io/parsers.py", line 1853, in __init__
    self._reader = parsers.TextReader(src, **kwds)
  File "pandas/_libs/parsers.pyx", line 545, in pandas._libs.parsers.TextReader.__cinit__
pandas.errors.EmptyDataError: No columns to parse from file
2019-06-25 19:49:53 - ERROR - bin.app[line:47]: Expecting value: line 1 column 1 (char 0)
Traceback (most recent call last):
  File "/Users/apple/Desktop/pollution_statistic_forecast_app-develop_lstm/bin/app.py", line 38, in correlation
    data = json.loads(request.data)
  File "/Users/apple/anaconda3/lib/python3.6/json/__init__.py", line 354, in loads
    return _default_decoder.decode(s)
  File "/Users/apple/anaconda3/lib/python3.6/json/decoder.py", line 339, in decode
    obj, end = self.raw_decode(s, idx=_w(s, 0).end())
  File "/Users/apple/anaconda3/lib/python3.6/json/decoder.py", line 357, in raw_decode
    raise JSONDecodeError("Expecting value", s, err.value) from None
json.decoder.JSONDecodeError: Expecting value: line 1 column 1 (char 0)
2019-06-25 19:53:32 - INFO - werkzeug[line:87]:  * Running on http://0.0.0.0:8000/ (Press CTRL+C to quit)
2019-06-25 19:53:46 - INFO - werkzeug[line:87]:  * Running on http://0.0.0.0:8000/ (Press CTRL+C to quit)
2019-06-25 19:54:14 - ERROR - bin.app[line:48]: "['ptime' 'time_stamp'] not found in axis"
Traceback (most recent call last):
  File "/Users/apple/Desktop/pollution_statistic_forecast_app-develop_lstm/bin/app.py", line 40, in correlation
    data = get_normalized_samples(data)
  File "/Users/apple/Desktop/pollution_statistic_forecast_app-develop_lstm/mods/time_delayed_correlation_analysis.py", line 19, in get_normalized_samples
    data.drop(['ptime', 'time_stamp'], axis = 1, inplace = True)
  File "/Users/apple/anaconda3/lib/python3.6/site-packages/pandas/core/frame.py", line 3940, in drop
    errors=errors)
  File "/Users/apple/anaconda3/lib/python3.6/site-packages/pandas/core/generic.py", line 3780, in drop
    obj = obj._drop_axis(labels, axis, level=level, errors=errors)
  File "/Users/apple/anaconda3/lib/python3.6/site-packages/pandas/core/generic.py", line 3812, in _drop_axis
    new_axis = axis.drop(labels, errors=errors)
  File "/Users/apple/anaconda3/lib/python3.6/site-packages/pandas/core/indexes/base.py", line 4965, in drop
    '{} not found in axis'.format(labels[mask]))
KeyError: "['ptime' 'time_stamp'] not found in axis"
2019-06-25 20:03:11 - ERROR - bin.app[line:49]: 'ptime'
Traceback (most recent call last):
  File "/Users/apple/anaconda3/lib/python3.6/site-packages/pandas/core/indexes/base.py", line 2657, in get_loc
    return self._engine.get_loc(key)
  File "pandas/_libs/index.pyx", line 108, in pandas._libs.index.IndexEngine.get_loc
  File "pandas/_libs/index.pyx", line 132, in pandas._libs.index.IndexEngine.get_loc
  File "pandas/_libs/hashtable_class_helper.pxi", line 1601, in pandas._libs.hashtable.PyObjectHashTable.get_item
  File "pandas/_libs/hashtable_class_helper.pxi", line 1608, in pandas._libs.hashtable.PyObjectHashTable.get_item
KeyError: 'ptime'

During handling of the above exception, another exception occurred:

Traceback (most recent call last):
  File "/Users/apple/Desktop/pollution_statistic_forecast_app-develop_lstm/bin/app.py", line 41, in correlation
    data = build_samples.build_data_frame_for_correlation_analysis_web_service(data, '2017010101', '2018010101')
  File "/Users/apple/Desktop/pollution_statistic_forecast_app-develop_lstm/mods/build_samples.py", line 67, in build_data_frame_for_correlation_analysis_web_service
    data['time_stamp'] = data.loc[:, 'ptime'].apply(
  File "/Users/apple/anaconda3/lib/python3.6/site-packages/pandas/core/indexing.py", line 1494, in __getitem__
    return self._getitem_tuple(key)
  File "/Users/apple/anaconda3/lib/python3.6/site-packages/pandas/core/indexing.py", line 868, in _getitem_tuple
    return self._getitem_lowerdim(tup)
  File "/Users/apple/anaconda3/lib/python3.6/site-packages/pandas/core/indexing.py", line 988, in _getitem_lowerdim
    section = self._getitem_axis(key, axis=i)
  File "/Users/apple/anaconda3/lib/python3.6/site-packages/pandas/core/indexing.py", line 1913, in _getitem_axis
    return self._get_label(key, axis=axis)
  File "/Users/apple/anaconda3/lib/python3.6/site-packages/pandas/core/indexing.py", line 141, in _get_label
    return self.obj._xs(label, axis=axis)
  File "/Users/apple/anaconda3/lib/python3.6/site-packages/pandas/core/generic.py", line 3576, in xs
    return self[key]
  File "/Users/apple/anaconda3/lib/python3.6/site-packages/pandas/core/frame.py", line 2927, in __getitem__
    indexer = self.columns.get_loc(key)
  File "/Users/apple/anaconda3/lib/python3.6/site-packages/pandas/core/indexes/base.py", line 2659, in get_loc
    return self._engine.get_loc(self._maybe_cast_indexer(key))
  File "pandas/_libs/index.pyx", line 108, in pandas._libs.index.IndexEngine.get_loc
  File "pandas/_libs/index.pyx", line 132, in pandas._libs.index.IndexEngine.get_loc
  File "pandas/_libs/hashtable_class_helper.pxi", line 1601, in pandas._libs.hashtable.PyObjectHashTable.get_item
  File "pandas/_libs/hashtable_class_helper.pxi", line 1608, in pandas._libs.hashtable.PyObjectHashTable.get_item
KeyError: 'ptime'
2019-06-25 20:03:54 - ERROR - bin.app[line:49]: 'ptime'
Traceback (most recent call last):
  File "/Users/apple/anaconda3/lib/python3.6/site-packages/pandas/core/indexes/base.py", line 2657, in get_loc
    return self._engine.get_loc(key)
  File "pandas/_libs/index.pyx", line 108, in pandas._libs.index.IndexEngine.get_loc
  File "pandas/_libs/index.pyx", line 132, in pandas._libs.index.IndexEngine.get_loc
  File "pandas/_libs/hashtable_class_helper.pxi", line 1601, in pandas._libs.hashtable.PyObjectHashTable.get_item
  File "pandas/_libs/hashtable_class_helper.pxi", line 1608, in pandas._libs.hashtable.PyObjectHashTable.get_item
KeyError: 'ptime'

During handling of the above exception, another exception occurred:

Traceback (most recent call last):
  File "/Users/apple/Desktop/pollution_statistic_forecast_app-develop_lstm/bin/app.py", line 41, in correlation
    data = build_samples.build_data_frame_for_correlation_analysis_web_service(data, '2017010101', '2018010101')
  File "/Users/apple/Desktop/pollution_statistic_forecast_app-develop_lstm/mods/build_samples.py", line 67, in build_data_frame_for_correlation_analysis_web_service
    data['time_stamp'] = data.loc[:, 'ptime'].apply(
  File "/Users/apple/anaconda3/lib/python3.6/site-packages/pandas/core/indexing.py", line 1494, in __getitem__
    return self._getitem_tuple(key)
  File "/Users/apple/anaconda3/lib/python3.6/site-packages/pandas/core/indexing.py", line 868, in _getitem_tuple
    return self._getitem_lowerdim(tup)
  File "/Users/apple/anaconda3/lib/python3.6/site-packages/pandas/core/indexing.py", line 988, in _getitem_lowerdim
    section = self._getitem_axis(key, axis=i)
  File "/Users/apple/anaconda3/lib/python3.6/site-packages/pandas/core/indexing.py", line 1913, in _getitem_axis
    return self._get_label(key, axis=axis)
  File "/Users/apple/anaconda3/lib/python3.6/site-packages/pandas/core/indexing.py", line 141, in _get_label
    return self.obj._xs(label, axis=axis)
  File "/Users/apple/anaconda3/lib/python3.6/site-packages/pandas/core/generic.py", line 3576, in xs
    return self[key]
  File "/Users/apple/anaconda3/lib/python3.6/site-packages/pandas/core/frame.py", line 2927, in __getitem__
    indexer = self.columns.get_loc(key)
  File "/Users/apple/anaconda3/lib/python3.6/site-packages/pandas/core/indexes/base.py", line 2659, in get_loc
    return self._engine.get_loc(self._maybe_cast_indexer(key))
  File "pandas/_libs/index.pyx", line 108, in pandas._libs.index.IndexEngine.get_loc
  File "pandas/_libs/index.pyx", line 132, in pandas._libs.index.IndexEngine.get_loc
  File "pandas/_libs/hashtable_class_helper.pxi", line 1601, in pandas._libs.hashtable.PyObjectHashTable.get_item
  File "pandas/_libs/hashtable_class_helper.pxi", line 1608, in pandas._libs.hashtable.PyObjectHashTable.get_item
KeyError: 'ptime'
2019-06-25 20:07:40 - ERROR - bin.app[line:50]: 'ptime'
Traceback (most recent call last):
  File "/Users/apple/anaconda3/lib/python3.6/site-packages/pandas/core/indexes/base.py", line 2657, in get_loc
    return self._engine.get_loc(key)
  File "pandas/_libs/index.pyx", line 108, in pandas._libs.index.IndexEngine.get_loc
  File "pandas/_libs/index.pyx", line 132, in pandas._libs.index.IndexEngine.get_loc
  File "pandas/_libs/hashtable_class_helper.pxi", line 1601, in pandas._libs.hashtable.PyObjectHashTable.get_item
  File "pandas/_libs/hashtable_class_helper.pxi", line 1608, in pandas._libs.hashtable.PyObjectHashTable.get_item
KeyError: 'ptime'

During handling of the above exception, another exception occurred:

Traceback (most recent call last):
  File "/Users/apple/Desktop/pollution_statistic_forecast_app-develop_lstm/bin/app.py", line 42, in correlation
    data = build_samples.build_data_frame_for_correlation_analysis_web_service(data, '2017010101', '2018010101')
  File "/Users/apple/Desktop/pollution_statistic_forecast_app-develop_lstm/mods/build_samples.py", line 67, in build_data_frame_for_correlation_analysis_web_service
    data['time_stamp'] = data.loc[:, 'ptime'].apply(
  File "/Users/apple/anaconda3/lib/python3.6/site-packages/pandas/core/indexing.py", line 1494, in __getitem__
    return self._getitem_tuple(key)
  File "/Users/apple/anaconda3/lib/python3.6/site-packages/pandas/core/indexing.py", line 868, in _getitem_tuple
    return self._getitem_lowerdim(tup)
  File "/Users/apple/anaconda3/lib/python3.6/site-packages/pandas/core/indexing.py", line 988, in _getitem_lowerdim
    section = self._getitem_axis(key, axis=i)
  File "/Users/apple/anaconda3/lib/python3.6/site-packages/pandas/core/indexing.py", line 1913, in _getitem_axis
    return self._get_label(key, axis=axis)
  File "/Users/apple/anaconda3/lib/python3.6/site-packages/pandas/core/indexing.py", line 141, in _get_label
    return self.obj._xs(label, axis=axis)
  File "/Users/apple/anaconda3/lib/python3.6/site-packages/pandas/core/generic.py", line 3576, in xs
    return self[key]
  File "/Users/apple/anaconda3/lib/python3.6/site-packages/pandas/core/frame.py", line 2927, in __getitem__
    indexer = self.columns.get_loc(key)
  File "/Users/apple/anaconda3/lib/python3.6/site-packages/pandas/core/indexes/base.py", line 2659, in get_loc
    return self._engine.get_loc(self._maybe_cast_indexer(key))
  File "pandas/_libs/index.pyx", line 108, in pandas._libs.index.IndexEngine.get_loc
  File "pandas/_libs/index.pyx", line 132, in pandas._libs.index.IndexEngine.get_loc
  File "pandas/_libs/hashtable_class_helper.pxi", line 1601, in pandas._libs.hashtable.PyObjectHashTable.get_item
  File "pandas/_libs/hashtable_class_helper.pxi", line 1608, in pandas._libs.hashtable.PyObjectHashTable.get_item
KeyError: 'ptime'
2019-06-25 20:19:39 - ERROR - bin.app[line:52]: DataFrame constructor not properly called!
Traceback (most recent call last):
  File "/Users/apple/Desktop/pollution_statistic_forecast_app-develop_lstm/bin/app.py", line 42, in correlation
    data = pd.DataFrame(data_string)
  File "/Users/apple/anaconda3/lib/python3.6/site-packages/pandas/core/frame.py", line 468, in __init__
    raise ValueError('DataFrame constructor not properly called!')
ValueError: DataFrame constructor not properly called!
2019-06-25 20:20:35 - INFO - werkzeug[line:87]:  * Running on http://0.0.0.0:8000/ (Press CTRL+C to quit)
2019-06-25 20:21:07 - ERROR - bin.app[line:53]: unexpected EOF while parsing (<unknown>, line 0)
Traceback (most recent call last):
  File "/Users/apple/Desktop/pollution_statistic_forecast_app-develop_lstm/bin/app.py", line 42, in correlation
    data_json = ast.literal_eval(data_string)
  File "/Users/apple/anaconda3/lib/python3.6/ast.py", line 48, in literal_eval
    node_or_string = parse(node_or_string, mode='eval')
  File "/Users/apple/anaconda3/lib/python3.6/ast.py", line 35, in parse
    return compile(source, filename, mode, PyCF_ONLY_AST)
  File "<unknown>", line 0
    
    ^
SyntaxError: unexpected EOF while parsing
2019-06-25 20:25:35 - ERROR - bin.app[line:52]: unexpected EOF while parsing (<unknown>, line 0)
Traceback (most recent call last):
  File "/Users/apple/Desktop/pollution_statistic_forecast_app-develop_lstm/bin/app.py", line 42, in correlation
    data = pd.DataFrame(ast.literal_eval(data_string))
  File "/Users/apple/anaconda3/lib/python3.6/ast.py", line 48, in literal_eval
    node_or_string = parse(node_or_string, mode='eval')
  File "/Users/apple/anaconda3/lib/python3.6/ast.py", line 35, in parse
    return compile(source, filename, mode, PyCF_ONLY_AST)
  File "<unknown>", line 0
    
    ^
SyntaxError: unexpected EOF while parsing
2019-06-25 20:26:14 - ERROR - bin.app[line:52]: unexpected EOF while parsing (<unknown>, line 0)
Traceback (most recent call last):
  File "/Users/apple/Desktop/pollution_statistic_forecast_app-develop_lstm/bin/app.py", line 42, in correlation
    data = pd.DataFrame(ast.literal_eval(data_string))
  File "/Users/apple/anaconda3/lib/python3.6/ast.py", line 48, in literal_eval
    node_or_string = parse(node_or_string, mode='eval')
  File "/Users/apple/anaconda3/lib/python3.6/ast.py", line 35, in parse
    return compile(source, filename, mode, PyCF_ONLY_AST)
  File "<unknown>", line 0
    
    ^
SyntaxError: unexpected EOF while parsing
2019-06-26 10:19:27 - ERROR - bin.app[line:52]: unexpected EOF while parsing (<unknown>, line 0)
Traceback (most recent call last):
  File "/Users/apple/Desktop/pollution_statistic_forecast_app-develop_lstm/bin/app.py", line 42, in correlation
    data = pd.DataFrame(ast.literal_eval(data_string))
  File "/Users/apple/anaconda3/lib/python3.6/ast.py", line 48, in literal_eval
    node_or_string = parse(node_or_string, mode='eval')
  File "/Users/apple/anaconda3/lib/python3.6/ast.py", line 35, in parse
    return compile(source, filename, mode, PyCF_ONLY_AST)
  File "<unknown>", line 0
    
    ^
SyntaxError: unexpected EOF while parsing
2019-06-26 10:21:03 - ERROR - bin.app[line:52]: DataFrame constructor not properly called!
Traceback (most recent call last):
  File "/Users/apple/Desktop/pollution_statistic_forecast_app-develop_lstm/bin/app.py", line 42, in correlation
    data = pd.DataFrame(data_string)
  File "/Users/apple/anaconda3/lib/python3.6/site-packages/pandas/core/frame.py", line 468, in __init__
    raise ValueError('DataFrame constructor not properly called!')
ValueError: DataFrame constructor not properly called!
2019-06-26 10:21:52 - ERROR - bin.app[line:53]: DataFrame constructor not properly called!
Traceback (most recent call last):
  File "/Users/apple/Desktop/pollution_statistic_forecast_app-develop_lstm/bin/app.py", line 43, in correlation
    data = pd.DataFrame(data_string)
  File "/Users/apple/anaconda3/lib/python3.6/site-packages/pandas/core/frame.py", line 468, in __init__
    raise ValueError('DataFrame constructor not properly called!')
ValueError: DataFrame constructor not properly called!
2019-06-26 10:24:37 - ERROR - bin.app[line:53]: 'str' object is not callable
Traceback (most recent call last):
  File "/Users/apple/Desktop/pollution_statistic_forecast_app-develop_lstm/bin/app.py", line 41, in correlation
    data_string = request.url()
TypeError: 'str' object is not callable
2019-06-26 10:25:47 - ERROR - bin.app[line:53]: 'ptime'
Traceback (most recent call last):
  File "/Users/apple/anaconda3/lib/python3.6/site-packages/pandas/core/indexes/base.py", line 2657, in get_loc
    return self._engine.get_loc(key)
  File "pandas/_libs/index.pyx", line 108, in pandas._libs.index.IndexEngine.get_loc
  File "pandas/_libs/index.pyx", line 132, in pandas._libs.index.IndexEngine.get_loc
  File "pandas/_libs/hashtable_class_helper.pxi", line 1601, in pandas._libs.hashtable.PyObjectHashTable.get_item
  File "pandas/_libs/hashtable_class_helper.pxi", line 1608, in pandas._libs.hashtable.PyObjectHashTable.get_item
KeyError: 'ptime'

During handling of the above exception, another exception occurred:

Traceback (most recent call last):
  File "/Users/apple/Desktop/pollution_statistic_forecast_app-develop_lstm/bin/app.py", line 45, in correlation
    data = build_samples.build_data_frame_for_correlation_analysis_web_service(data, '2017010101', '2018010101')
  File "/Users/apple/Desktop/pollution_statistic_forecast_app-develop_lstm/mods/build_samples.py", line 67, in build_data_frame_for_correlation_analysis_web_service
    data['time_stamp'] = data.loc[:, 'ptime'].apply(
  File "/Users/apple/anaconda3/lib/python3.6/site-packages/pandas/core/indexing.py", line 1494, in __getitem__
    return self._getitem_tuple(key)
  File "/Users/apple/anaconda3/lib/python3.6/site-packages/pandas/core/indexing.py", line 868, in _getitem_tuple
    return self._getitem_lowerdim(tup)
  File "/Users/apple/anaconda3/lib/python3.6/site-packages/pandas/core/indexing.py", line 988, in _getitem_lowerdim
    section = self._getitem_axis(key, axis=i)
  File "/Users/apple/anaconda3/lib/python3.6/site-packages/pandas/core/indexing.py", line 1913, in _getitem_axis
    return self._get_label(key, axis=axis)
  File "/Users/apple/anaconda3/lib/python3.6/site-packages/pandas/core/indexing.py", line 141, in _get_label
    return self.obj._xs(label, axis=axis)
  File "/Users/apple/anaconda3/lib/python3.6/site-packages/pandas/core/generic.py", line 3576, in xs
    return self[key]
  File "/Users/apple/anaconda3/lib/python3.6/site-packages/pandas/core/frame.py", line 2927, in __getitem__
    indexer = self.columns.get_loc(key)
  File "/Users/apple/anaconda3/lib/python3.6/site-packages/pandas/core/indexes/base.py", line 2659, in get_loc
    return self._engine.get_loc(self._maybe_cast_indexer(key))
  File "pandas/_libs/index.pyx", line 108, in pandas._libs.index.IndexEngine.get_loc
  File "pandas/_libs/index.pyx", line 132, in pandas._libs.index.IndexEngine.get_loc
  File "pandas/_libs/hashtable_class_helper.pxi", line 1601, in pandas._libs.hashtable.PyObjectHashTable.get_item
  File "pandas/_libs/hashtable_class_helper.pxi", line 1608, in pandas._libs.hashtable.PyObjectHashTable.get_item
KeyError: 'ptime'
2019-06-26 10:26:37 - ERROR - bin.app[line:53]: 'ptime'
Traceback (most recent call last):
  File "/Users/apple/anaconda3/lib/python3.6/site-packages/pandas/core/indexes/base.py", line 2657, in get_loc
    return self._engine.get_loc(key)
  File "pandas/_libs/index.pyx", line 108, in pandas._libs.index.IndexEngine.get_loc
  File "pandas/_libs/index.pyx", line 132, in pandas._libs.index.IndexEngine.get_loc
  File "pandas/_libs/hashtable_class_helper.pxi", line 1601, in pandas._libs.hashtable.PyObjectHashTable.get_item
  File "pandas/_libs/hashtable_class_helper.pxi", line 1608, in pandas._libs.hashtable.PyObjectHashTable.get_item
KeyError: 'ptime'

During handling of the above exception, another exception occurred:

Traceback (most recent call last):
  File "/Users/apple/Desktop/pollution_statistic_forecast_app-develop_lstm/bin/app.py", line 45, in correlation
    data = build_samples.build_data_frame_for_correlation_analysis_web_service(data, '2017010101', '2018010101')
  File "/Users/apple/Desktop/pollution_statistic_forecast_app-develop_lstm/mods/build_samples.py", line 67, in build_data_frame_for_correlation_analysis_web_service
    data['time_stamp'] = data.loc[:, 'ptime'].apply(
  File "/Users/apple/anaconda3/lib/python3.6/site-packages/pandas/core/indexing.py", line 1494, in __getitem__
    return self._getitem_tuple(key)
  File "/Users/apple/anaconda3/lib/python3.6/site-packages/pandas/core/indexing.py", line 868, in _getitem_tuple
    return self._getitem_lowerdim(tup)
  File "/Users/apple/anaconda3/lib/python3.6/site-packages/pandas/core/indexing.py", line 988, in _getitem_lowerdim
    section = self._getitem_axis(key, axis=i)
  File "/Users/apple/anaconda3/lib/python3.6/site-packages/pandas/core/indexing.py", line 1913, in _getitem_axis
    return self._get_label(key, axis=axis)
  File "/Users/apple/anaconda3/lib/python3.6/site-packages/pandas/core/indexing.py", line 141, in _get_label
    return self.obj._xs(label, axis=axis)
  File "/Users/apple/anaconda3/lib/python3.6/site-packages/pandas/core/generic.py", line 3576, in xs
    return self[key]
  File "/Users/apple/anaconda3/lib/python3.6/site-packages/pandas/core/frame.py", line 2927, in __getitem__
    indexer = self.columns.get_loc(key)
  File "/Users/apple/anaconda3/lib/python3.6/site-packages/pandas/core/indexes/base.py", line 2659, in get_loc
    return self._engine.get_loc(self._maybe_cast_indexer(key))
  File "pandas/_libs/index.pyx", line 108, in pandas._libs.index.IndexEngine.get_loc
  File "pandas/_libs/index.pyx", line 132, in pandas._libs.index.IndexEngine.get_loc
  File "pandas/_libs/hashtable_class_helper.pxi", line 1601, in pandas._libs.hashtable.PyObjectHashTable.get_item
  File "pandas/_libs/hashtable_class_helper.pxi", line 1608, in pandas._libs.hashtable.PyObjectHashTable.get_item
KeyError: 'ptime'
2019-06-26 10:28:59 - ERROR - bin.app[line:53]: Expecting value: line 1 column 1 (char 0)
Traceback (most recent call last):
  File "/Users/apple/Desktop/pollution_statistic_forecast_app-develop_lstm/bin/app.py", line 41, in correlation
    data_string = json.loads(request.data)
  File "/Users/apple/anaconda3/lib/python3.6/json/__init__.py", line 354, in loads
    return _default_decoder.decode(s)
  File "/Users/apple/anaconda3/lib/python3.6/json/decoder.py", line 339, in decode
    obj, end = self.raw_decode(s, idx=_w(s, 0).end())
  File "/Users/apple/anaconda3/lib/python3.6/json/decoder.py", line 357, in raw_decode
    raise JSONDecodeError("Expecting value", s, err.value) from None
json.decoder.JSONDecodeError: Expecting value: line 1 column 1 (char 0)
2019-06-26 10:29:28 - ERROR - bin.app[line:52]: Expecting value: line 1 column 1 (char 0)
Traceback (most recent call last):
  File "/Users/apple/Desktop/pollution_statistic_forecast_app-develop_lstm/bin/app.py", line 40, in correlation
    data_string = json.loads(request.data)
  File "/Users/apple/anaconda3/lib/python3.6/json/__init__.py", line 354, in loads
    return _default_decoder.decode(s)
  File "/Users/apple/anaconda3/lib/python3.6/json/decoder.py", line 339, in decode
    obj, end = self.raw_decode(s, idx=_w(s, 0).end())
  File "/Users/apple/anaconda3/lib/python3.6/json/decoder.py", line 357, in raw_decode
    raise JSONDecodeError("Expecting value", s, err.value) from None
json.decoder.JSONDecodeError: Expecting value: line 1 column 1 (char 0)
2019-06-26 10:33:11 - ERROR - bin.app[line:54]: 'bytes' object has no attribute 'content'
Traceback (most recent call last):
  File "/Users/apple/Desktop/pollution_statistic_forecast_app-develop_lstm/bin/app.py", line 41, in correlation
    if response.content:
AttributeError: 'bytes' object has no attribute 'content'
2019-06-26 10:38:40 - ERROR - bin.app[line:53]: Expecting value: line 1 column 1 (char 0)
Traceback (most recent call last):
  File "/Users/apple/Desktop/pollution_statistic_forecast_app-develop_lstm/bin/app.py", line 39, in correlation
    data_dict = json.loads(request.data)
  File "/Users/apple/anaconda3/lib/python3.6/json/__init__.py", line 354, in loads
    return _default_decoder.decode(s)
  File "/Users/apple/anaconda3/lib/python3.6/json/decoder.py", line 339, in decode
    obj, end = self.raw_decode(s, idx=_w(s, 0).end())
  File "/Users/apple/anaconda3/lib/python3.6/json/decoder.py", line 357, in raw_decode
    raise JSONDecodeError("Expecting value", s, err.value) from None
json.decoder.JSONDecodeError: Expecting value: line 1 column 1 (char 0)
2019-06-26 10:39:10 - ERROR - bin.app[line:53]: Expecting value: line 1 column 1 (char 0)
Traceback (most recent call last):
  File "/Users/apple/Desktop/pollution_statistic_forecast_app-develop_lstm/bin/app.py", line 39, in correlation
    data_dict = json.loads(request.data)
  File "/Users/apple/anaconda3/lib/python3.6/json/__init__.py", line 354, in loads
    return _default_decoder.decode(s)
  File "/Users/apple/anaconda3/lib/python3.6/json/decoder.py", line 339, in decode
    obj, end = self.raw_decode(s, idx=_w(s, 0).end())
  File "/Users/apple/anaconda3/lib/python3.6/json/decoder.py", line 357, in raw_decode
    raise JSONDecodeError("Expecting value", s, err.value) from None
json.decoder.JSONDecodeError: Expecting value: line 1 column 1 (char 0)
2019-06-26 10:39:40 - ERROR - bin.app[line:53]: Expecting value: line 1 column 1 (char 0)
Traceback (most recent call last):
  File "/Users/apple/Desktop/pollution_statistic_forecast_app-develop_lstm/bin/app.py", line 39, in correlation
    data_dict = json.loads(request.data)
  File "/Users/apple/anaconda3/lib/python3.6/json/__init__.py", line 354, in loads
    return _default_decoder.decode(s)
  File "/Users/apple/anaconda3/lib/python3.6/json/decoder.py", line 339, in decode
    obj, end = self.raw_decode(s, idx=_w(s, 0).end())
  File "/Users/apple/anaconda3/lib/python3.6/json/decoder.py", line 357, in raw_decode
    raise JSONDecodeError("Expecting value", s, err.value) from None
json.decoder.JSONDecodeError: Expecting value: line 1 column 1 (char 0)
2019-06-26 10:40:38 - ERROR - bin.app[line:53]: Expecting value: line 1 column 1 (char 0)
Traceback (most recent call last):
  File "/Users/apple/Desktop/pollution_statistic_forecast_app-develop_lstm/bin/app.py", line 39, in correlation
    data_dict = json.loads(request.data)
  File "/Users/apple/anaconda3/lib/python3.6/json/__init__.py", line 354, in loads
    return _default_decoder.decode(s)
  File "/Users/apple/anaconda3/lib/python3.6/json/decoder.py", line 339, in decode
    obj, end = self.raw_decode(s, idx=_w(s, 0).end())
  File "/Users/apple/anaconda3/lib/python3.6/json/decoder.py", line 357, in raw_decode
    raise JSONDecodeError("Expecting value", s, err.value) from None
json.decoder.JSONDecodeError: Expecting value: line 1 column 1 (char 0)
2019-06-26 10:41:26 - ERROR - bin.app[line:53]: Expecting value: line 1 column 1 (char 0)
Traceback (most recent call last):
  File "/Users/apple/Desktop/pollution_statistic_forecast_app-develop_lstm/bin/app.py", line 39, in correlation
    data_dict = json.loads(request.data)
  File "/Users/apple/anaconda3/lib/python3.6/json/__init__.py", line 354, in loads
    return _default_decoder.decode(s)
  File "/Users/apple/anaconda3/lib/python3.6/json/decoder.py", line 339, in decode
    obj, end = self.raw_decode(s, idx=_w(s, 0).end())
  File "/Users/apple/anaconda3/lib/python3.6/json/decoder.py", line 357, in raw_decode
    raise JSONDecodeError("Expecting value", s, err.value) from None
json.decoder.JSONDecodeError: Expecting value: line 1 column 1 (char 0)
2019-06-26 10:42:26 - ERROR - bin.app[line:53]: Expecting value: line 1 column 1 (char 0)
Traceback (most recent call last):
  File "/Users/apple/Desktop/pollution_statistic_forecast_app-develop_lstm/bin/app.py", line 39, in correlation
    data_dict = json.loads(request.data)
  File "/Users/apple/anaconda3/lib/python3.6/json/__init__.py", line 354, in loads
    return _default_decoder.decode(s)
  File "/Users/apple/anaconda3/lib/python3.6/json/decoder.py", line 339, in decode
    obj, end = self.raw_decode(s, idx=_w(s, 0).end())
  File "/Users/apple/anaconda3/lib/python3.6/json/decoder.py", line 357, in raw_decode
    raise JSONDecodeError("Expecting value", s, err.value) from None
json.decoder.JSONDecodeError: Expecting value: line 1 column 1 (char 0)
2019-06-26 10:43:02 - ERROR - bin.app[line:53]: Expecting value: line 1 column 1 (char 0)
Traceback (most recent call last):
  File "/Users/apple/Desktop/pollution_statistic_forecast_app-develop_lstm/bin/app.py", line 39, in correlation
    data_dict = json.loads(request.data)
  File "/Users/apple/anaconda3/lib/python3.6/json/__init__.py", line 354, in loads
    return _default_decoder.decode(s)
  File "/Users/apple/anaconda3/lib/python3.6/json/decoder.py", line 339, in decode
    obj, end = self.raw_decode(s, idx=_w(s, 0).end())
  File "/Users/apple/anaconda3/lib/python3.6/json/decoder.py", line 357, in raw_decode
    raise JSONDecodeError("Expecting value", s, err.value) from None
json.decoder.JSONDecodeError: Expecting value: line 1 column 1 (char 0)
2019-06-26 10:43:22 - ERROR - bin.app[line:54]: Expecting value: line 1 column 1 (char 0)
Traceback (most recent call last):
  File "/Users/apple/Desktop/pollution_statistic_forecast_app-develop_lstm/bin/app.py", line 39, in correlation
    data_dict = json.loads(request.data)
  File "/Users/apple/anaconda3/lib/python3.6/json/__init__.py", line 354, in loads
    return _default_decoder.decode(s)
  File "/Users/apple/anaconda3/lib/python3.6/json/decoder.py", line 339, in decode
    obj, end = self.raw_decode(s, idx=_w(s, 0).end())
  File "/Users/apple/anaconda3/lib/python3.6/json/decoder.py", line 357, in raw_decode
    raise JSONDecodeError("Expecting value", s, err.value) from None
json.decoder.JSONDecodeError: Expecting value: line 1 column 1 (char 0)
2019-06-26 10:43:44 - ERROR - bin.app[line:54]: Expecting value: line 1 column 1 (char 0)
Traceback (most recent call last):
  File "/Users/apple/Desktop/pollution_statistic_forecast_app-develop_lstm/bin/app.py", line 40, in correlation
    data_dict = json.loads(request.data)
  File "/Users/apple/anaconda3/lib/python3.6/json/__init__.py", line 354, in loads
    return _default_decoder.decode(s)
  File "/Users/apple/anaconda3/lib/python3.6/json/decoder.py", line 339, in decode
    obj, end = self.raw_decode(s, idx=_w(s, 0).end())
  File "/Users/apple/anaconda3/lib/python3.6/json/decoder.py", line 357, in raw_decode
    raise JSONDecodeError("Expecting value", s, err.value) from None
json.decoder.JSONDecodeError: Expecting value: line 1 column 1 (char 0)
2019-06-26 10:48:10 - ERROR - bin.app[line:54]: Expecting value: line 1 column 1 (char 0)
Traceback (most recent call last):
  File "/Users/apple/Desktop/pollution_statistic_forecast_app-develop_lstm/bin/app.py", line 40, in correlation
    data_dict = json.loads(request.data)
  File "/Users/apple/anaconda3/lib/python3.6/json/__init__.py", line 354, in loads
    return _default_decoder.decode(s)
  File "/Users/apple/anaconda3/lib/python3.6/json/decoder.py", line 339, in decode
    obj, end = self.raw_decode(s, idx=_w(s, 0).end())
  File "/Users/apple/anaconda3/lib/python3.6/json/decoder.py", line 357, in raw_decode
    raise JSONDecodeError("Expecting value", s, err.value) from None
json.decoder.JSONDecodeError: Expecting value: line 1 column 1 (char 0)
2019-06-26 10:49:01 - ERROR - bin.app[line:54]: Expecting value: line 1 column 1 (char 0)
Traceback (most recent call last):
  File "/Users/apple/Desktop/pollution_statistic_forecast_app-develop_lstm/bin/app.py", line 40, in correlation
    data_dict = json.loads(request.data)
  File "/Users/apple/anaconda3/lib/python3.6/json/__init__.py", line 354, in loads
    return _default_decoder.decode(s)
  File "/Users/apple/anaconda3/lib/python3.6/json/decoder.py", line 339, in decode
    obj, end = self.raw_decode(s, idx=_w(s, 0).end())
  File "/Users/apple/anaconda3/lib/python3.6/json/decoder.py", line 357, in raw_decode
    raise JSONDecodeError("Expecting value", s, err.value) from None
json.decoder.JSONDecodeError: Expecting value: line 1 column 1 (char 0)
2019-06-26 10:49:23 - ERROR - bin.app[line:54]: Expecting value: line 1 column 1 (char 0)
Traceback (most recent call last):
  File "/Users/apple/Desktop/pollution_statistic_forecast_app-develop_lstm/bin/app.py", line 40, in correlation
    data_dict = json.loads(request.data)
  File "/Users/apple/anaconda3/lib/python3.6/json/__init__.py", line 354, in loads
    return _default_decoder.decode(s)
  File "/Users/apple/anaconda3/lib/python3.6/json/decoder.py", line 339, in decode
    obj, end = self.raw_decode(s, idx=_w(s, 0).end())
  File "/Users/apple/anaconda3/lib/python3.6/json/decoder.py", line 357, in raw_decode
    raise JSONDecodeError("Expecting value", s, err.value) from None
json.decoder.JSONDecodeError: Expecting value: line 1 column 1 (char 0)
2019-06-26 10:50:24 - ERROR - bin.app[line:54]: Expecting value: line 1 column 1 (char 0)
Traceback (most recent call last):
  File "/Users/apple/Desktop/pollution_statistic_forecast_app-develop_lstm/bin/app.py", line 40, in correlation
    data_dict = json.loads(request.data)
  File "/Users/apple/anaconda3/lib/python3.6/json/__init__.py", line 354, in loads
    return _default_decoder.decode(s)
  File "/Users/apple/anaconda3/lib/python3.6/json/decoder.py", line 339, in decode
    obj, end = self.raw_decode(s, idx=_w(s, 0).end())
  File "/Users/apple/anaconda3/lib/python3.6/json/decoder.py", line 357, in raw_decode
    raise JSONDecodeError("Expecting value", s, err.value) from None
json.decoder.JSONDecodeError: Expecting value: line 1 column 1 (char 0)
2019-06-26 11:08:21 - ERROR - bin.app[line:48]: Expecting value: line 1 column 1 (char 0)
Traceback (most recent call last):
  File "/Users/apple/Desktop/pollution_statistic_forecast_app-develop_lstm/bin/app.py", line 38, in correlation
    data = json.loads(request.data)['data']
  File "/Users/apple/anaconda3/lib/python3.6/json/__init__.py", line 354, in loads
    return _default_decoder.decode(s)
  File "/Users/apple/anaconda3/lib/python3.6/json/decoder.py", line 339, in decode
    obj, end = self.raw_decode(s, idx=_w(s, 0).end())
  File "/Users/apple/anaconda3/lib/python3.6/json/decoder.py", line 357, in raw_decode
    raise JSONDecodeError("Expecting value", s, err.value) from None
json.decoder.JSONDecodeError: Expecting value: line 1 column 1 (char 0)
2019-06-26 11:10:02 - ERROR - bin.app[line:48]: Expecting value: line 1 column 1 (char 0)
Traceback (most recent call last):
  File "/Users/apple/Desktop/pollution_statistic_forecast_app-develop_lstm/bin/app.py", line 38, in correlation
    data = json.loads(request.data)
  File "/Users/apple/anaconda3/lib/python3.6/json/__init__.py", line 354, in loads
    return _default_decoder.decode(s)
  File "/Users/apple/anaconda3/lib/python3.6/json/decoder.py", line 339, in decode
    obj, end = self.raw_decode(s, idx=_w(s, 0).end())
  File "/Users/apple/anaconda3/lib/python3.6/json/decoder.py", line 357, in raw_decode
    raise JSONDecodeError("Expecting value", s, err.value) from None
json.decoder.JSONDecodeError: Expecting value: line 1 column 1 (char 0)
2019-06-26 11:19:02 - ERROR - bin.app[line:47]: Expecting value: line 1 column 1 (char 0)
Traceback (most recent call last):
  File "/Users/apple/Desktop/pollution_statistic_forecast_app-develop_lstm/bin/app.py", line 37, in correlation
    data = json.loads(request.data)
  File "/Users/apple/anaconda3/lib/python3.6/json/__init__.py", line 354, in loads
    return _default_decoder.decode(s)
  File "/Users/apple/anaconda3/lib/python3.6/json/decoder.py", line 339, in decode
    obj, end = self.raw_decode(s, idx=_w(s, 0).end())
  File "/Users/apple/anaconda3/lib/python3.6/json/decoder.py", line 357, in raw_decode
    raise JSONDecodeError("Expecting value", s, err.value) from None
json.decoder.JSONDecodeError: Expecting value: line 1 column 1 (char 0)
2019-06-26 11:19:19 - ERROR - bin.app[line:47]: Expecting value: line 1 column 1 (char 0)
Traceback (most recent call last):
  File "/Users/apple/Desktop/pollution_statistic_forecast_app-develop_lstm/bin/app.py", line 37, in correlation
    data = json.loads(request.data)['data']
  File "/Users/apple/anaconda3/lib/python3.6/json/__init__.py", line 354, in loads
    return _default_decoder.decode(s)
  File "/Users/apple/anaconda3/lib/python3.6/json/decoder.py", line 339, in decode
    obj, end = self.raw_decode(s, idx=_w(s, 0).end())
  File "/Users/apple/anaconda3/lib/python3.6/json/decoder.py", line 357, in raw_decode
    raise JSONDecodeError("Expecting value", s, err.value) from None
json.decoder.JSONDecodeError: Expecting value: line 1 column 1 (char 0)
2019-06-26 11:24:24 - ERROR - bin.app[line:47]: Expecting value: line 1 column 1 (char 0)
Traceback (most recent call last):
  File "/Users/apple/Desktop/pollution_statistic_forecast_app-develop_lstm/bin/app.py", line 37, in correlation
    data = json.loads(request.data)['data']
  File "/Users/apple/anaconda3/lib/python3.6/json/__init__.py", line 354, in loads
    return _default_decoder.decode(s)
  File "/Users/apple/anaconda3/lib/python3.6/json/decoder.py", line 339, in decode
    obj, end = self.raw_decode(s, idx=_w(s, 0).end())
  File "/Users/apple/anaconda3/lib/python3.6/json/decoder.py", line 357, in raw_decode
    raise JSONDecodeError("Expecting value", s, err.value) from None
json.decoder.JSONDecodeError: Expecting value: line 1 column 1 (char 0)
2019-06-26 11:25:15 - ERROR - bin.app[line:48]: Expecting value: line 1 column 1 (char 0)
Traceback (most recent call last):
  File "/Users/apple/Desktop/pollution_statistic_forecast_app-develop_lstm/bin/app.py", line 37, in correlation
    data = json.loads(request.data)['data']
  File "/Users/apple/anaconda3/lib/python3.6/json/__init__.py", line 354, in loads
    return _default_decoder.decode(s)
  File "/Users/apple/anaconda3/lib/python3.6/json/decoder.py", line 339, in decode
    obj, end = self.raw_decode(s, idx=_w(s, 0).end())
  File "/Users/apple/anaconda3/lib/python3.6/json/decoder.py", line 357, in raw_decode
    raise JSONDecodeError("Expecting value", s, err.value) from None
json.decoder.JSONDecodeError: Expecting value: line 1 column 1 (char 0)
2019-06-26 11:25:28 - ERROR - bin.app[line:48]: Expecting value: line 1 column 1 (char 0)
Traceback (most recent call last):
  File "/Users/apple/Desktop/pollution_statistic_forecast_app-develop_lstm/bin/app.py", line 37, in correlation
    data = json.loads(request.data)['data']
  File "/Users/apple/anaconda3/lib/python3.6/json/__init__.py", line 354, in loads
    return _default_decoder.decode(s)
  File "/Users/apple/anaconda3/lib/python3.6/json/decoder.py", line 339, in decode
    obj, end = self.raw_decode(s, idx=_w(s, 0).end())
  File "/Users/apple/anaconda3/lib/python3.6/json/decoder.py", line 357, in raw_decode
    raise JSONDecodeError("Expecting value", s, err.value) from None
json.decoder.JSONDecodeError: Expecting value: line 1 column 1 (char 0)
2019-06-26 11:27:51 - ERROR - bin.app[line:48]: Expecting value: line 1 column 1 (char 0)
Traceback (most recent call last):
  File "/Users/apple/Desktop/pollution_statistic_forecast_app-develop_lstm/bin/app.py", line 37, in correlation
    data = json.loads(request.data)
  File "/Users/apple/anaconda3/lib/python3.6/json/__init__.py", line 354, in loads
    return _default_decoder.decode(s)
  File "/Users/apple/anaconda3/lib/python3.6/json/decoder.py", line 339, in decode
    obj, end = self.raw_decode(s, idx=_w(s, 0).end())
  File "/Users/apple/anaconda3/lib/python3.6/json/decoder.py", line 357, in raw_decode
    raise JSONDecodeError("Expecting value", s, err.value) from None
json.decoder.JSONDecodeError: Expecting value: line 1 column 1 (char 0)
2019-06-26 11:33:16 - ERROR - bin.app[line:48]: Expecting value: line 1 column 1 (char 0)
Traceback (most recent call last):
  File "/Users/apple/Desktop/pollution_statistic_forecast_app-develop_lstm/bin/app.py", line 37, in correlation
    data = json.loads(request.data)
  File "/Users/apple/anaconda3/lib/python3.6/json/__init__.py", line 354, in loads
    return _default_decoder.decode(s)
  File "/Users/apple/anaconda3/lib/python3.6/json/decoder.py", line 339, in decode
    obj, end = self.raw_decode(s, idx=_w(s, 0).end())
  File "/Users/apple/anaconda3/lib/python3.6/json/decoder.py", line 357, in raw_decode
    raise JSONDecodeError("Expecting value", s, err.value) from None
json.decoder.JSONDecodeError: Expecting value: line 1 column 1 (char 0)
2019-06-26 11:35:39 - ERROR - bin.app[line:48]: Expecting value: line 1 column 1 (char 0)
Traceback (most recent call last):
  File "/Users/apple/Desktop/pollution_statistic_forecast_app-develop_lstm/bin/app.py", line 37, in correlation
    data = json.loads(request.data)
  File "/Users/apple/anaconda3/lib/python3.6/json/__init__.py", line 354, in loads
    return _default_decoder.decode(s)
  File "/Users/apple/anaconda3/lib/python3.6/json/decoder.py", line 339, in decode
    obj, end = self.raw_decode(s, idx=_w(s, 0).end())
  File "/Users/apple/anaconda3/lib/python3.6/json/decoder.py", line 357, in raw_decode
    raise JSONDecodeError("Expecting value", s, err.value) from None
json.decoder.JSONDecodeError: Expecting value: line 1 column 1 (char 0)
2019-06-26 11:37:08 - ERROR - bin.app[line:48]: Expecting value: line 1 column 1 (char 0)
Traceback (most recent call last):
  File "/Users/apple/Desktop/pollution_statistic_forecast_app-develop_lstm/bin/app.py", line 37, in correlation
    data = json.loads(request.data)
  File "/Users/apple/anaconda3/lib/python3.6/json/__init__.py", line 354, in loads
    return _default_decoder.decode(s)
  File "/Users/apple/anaconda3/lib/python3.6/json/decoder.py", line 339, in decode
    obj, end = self.raw_decode(s, idx=_w(s, 0).end())
  File "/Users/apple/anaconda3/lib/python3.6/json/decoder.py", line 357, in raw_decode
    raise JSONDecodeError("Expecting value", s, err.value) from None
json.decoder.JSONDecodeError: Expecting value: line 1 column 1 (char 0)
2019-06-26 11:37:52 - ERROR - bin.app[line:49]: Expecting value: line 1 column 1 (char 0)
Traceback (most recent call last):
  File "/Users/apple/Desktop/pollution_statistic_forecast_app-develop_lstm/bin/app.py", line 38, in correlation
    data = json.loads(request.data)
  File "/Users/apple/anaconda3/lib/python3.6/json/__init__.py", line 354, in loads
    return _default_decoder.decode(s)
  File "/Users/apple/anaconda3/lib/python3.6/json/decoder.py", line 339, in decode
    obj, end = self.raw_decode(s, idx=_w(s, 0).end())
  File "/Users/apple/anaconda3/lib/python3.6/json/decoder.py", line 357, in raw_decode
    raise JSONDecodeError("Expecting value", s, err.value) from None
json.decoder.JSONDecodeError: Expecting value: line 1 column 1 (char 0)
2019-06-26 11:39:39 - ERROR - bin.app[line:47]: Expecting value: line 1 column 1 (char 0)
Traceback (most recent call last):
  File "/Users/apple/Desktop/pollution_statistic_forecast_app-develop_lstm/bin/app.py", line 37, in correlation
    data = json.loads(request.data)
  File "/Users/apple/anaconda3/lib/python3.6/json/__init__.py", line 354, in loads
    return _default_decoder.decode(s)
  File "/Users/apple/anaconda3/lib/python3.6/json/decoder.py", line 339, in decode
    obj, end = self.raw_decode(s, idx=_w(s, 0).end())
  File "/Users/apple/anaconda3/lib/python3.6/json/decoder.py", line 357, in raw_decode
    raise JSONDecodeError("Expecting value", s, err.value) from None
json.decoder.JSONDecodeError: Expecting value: line 1 column 1 (char 0)
2019-06-26 11:44:36 - ERROR - bin.app[line:47]: 'starttime'
Traceback (most recent call last):
  File "/Users/apple/Desktop/pollution_statistic_forecast_app-develop_lstm/bin/app.py", line 39, in correlation
    data = build_samples.build_data_frame_for_correlation_analysis(data['starttime'], data['endtime'])
KeyError: 'starttime'
2019-06-26 11:45:19 - ERROR - bin.app[line:47]: 'starttime'
Traceback (most recent call last):
  File "/Users/apple/Desktop/pollution_statistic_forecast_app-develop_lstm/bin/app.py", line 39, in correlation
    data = build_samples.build_data_frame_for_correlation_analysis(data['starttime'], data['endtime'])
KeyError: 'starttime'
2019-06-26 11:45:39 - ERROR - bin.app[line:48]: 'starttime'
Traceback (most recent call last):
  File "/Users/apple/Desktop/pollution_statistic_forecast_app-develop_lstm/bin/app.py", line 40, in correlation
    data = build_samples.build_data_frame_for_correlation_analysis(data['starttime'], data['endtime'])
KeyError: 'starttime'
2019-06-26 11:45:58 - ERROR - bin.app[line:48]: (1045, "Access denied for user 'root'@'localhost' (using password: YES)")
Traceback (most recent call last):
  File "/Users/apple/Desktop/pollution_statistic_forecast_app-develop_lstm/bin/app.py", line 40, in correlation
    data = build_samples.build_data_frame_for_correlation_analysis(data['starttime'], data['endtime'])
  File "/Users/apple/Desktop/pollution_statistic_forecast_app-develop_lstm/mods/build_samples.py", line 32, in build_data_frame_for_correlation_analysis
    data = pull_data_from_db(db_config, start_time, end_time)
  File "/Users/apple/Desktop/pollution_statistic_forecast_app-develop_lstm/mods/pull_data_from_db.py", line 25, in pull_data_from_db
    db = db_config['db'])                # name of the database
  File "/Users/apple/anaconda3/lib/python3.6/site-packages/pymysql/__init__.py", line 94, in Connect
    return Connection(*args, **kwargs)
  File "/Users/apple/anaconda3/lib/python3.6/site-packages/pymysql/connections.py", line 325, in __init__
    self.connect()
  File "/Users/apple/anaconda3/lib/python3.6/site-packages/pymysql/connections.py", line 599, in connect
    self._request_authentication()
  File "/Users/apple/anaconda3/lib/python3.6/site-packages/pymysql/connections.py", line 882, in _request_authentication
    auth_packet = _auth.caching_sha2_password_auth(self, auth_packet)
  File "/Users/apple/anaconda3/lib/python3.6/site-packages/pymysql/_auth.py", line 265, in caching_sha2_password_auth
    pkt = _roundtrip(conn, data)
  File "/Users/apple/anaconda3/lib/python3.6/site-packages/pymysql/_auth.py", line 122, in _roundtrip
    pkt = conn._read_packet()
  File "/Users/apple/anaconda3/lib/python3.6/site-packages/pymysql/connections.py", line 684, in _read_packet
    packet.check_error()
  File "/Users/apple/anaconda3/lib/python3.6/site-packages/pymysql/protocol.py", line 220, in check_error
    err.raise_mysql_exception(self._data)
  File "/Users/apple/anaconda3/lib/python3.6/site-packages/pymysql/err.py", line 109, in raise_mysql_exception
    raise errorclass(errno, errval)
pymysql.err.OperationalError: (1045, "Access denied for user 'root'@'localhost' (using password: YES)")
2019-06-26 11:46:55 - ERROR - bin.app[line:48]: (1045, "Access denied for user 'root'@'localhost' (using password: YES)")
Traceback (most recent call last):
  File "/Users/apple/Desktop/pollution_statistic_forecast_app-develop_lstm/bin/app.py", line 40, in correlation
    data = build_samples.build_data_frame_for_correlation_analysis(data['starttime'], data['endtime'])
  File "/Users/apple/Desktop/pollution_statistic_forecast_app-develop_lstm/mods/build_samples.py", line 32, in build_data_frame_for_correlation_analysis
    data = pull_data_from_db(db_config, start_time, end_time)
  File "/Users/apple/Desktop/pollution_statistic_forecast_app-develop_lstm/mods/pull_data_from_db.py", line 25, in pull_data_from_db
    db = db_config['db'])                # name of the database
  File "/Users/apple/anaconda3/lib/python3.6/site-packages/pymysql/__init__.py", line 94, in Connect
    return Connection(*args, **kwargs)
  File "/Users/apple/anaconda3/lib/python3.6/site-packages/pymysql/connections.py", line 325, in __init__
    self.connect()
  File "/Users/apple/anaconda3/lib/python3.6/site-packages/pymysql/connections.py", line 599, in connect
    self._request_authentication()
  File "/Users/apple/anaconda3/lib/python3.6/site-packages/pymysql/connections.py", line 882, in _request_authentication
    auth_packet = _auth.caching_sha2_password_auth(self, auth_packet)
  File "/Users/apple/anaconda3/lib/python3.6/site-packages/pymysql/_auth.py", line 265, in caching_sha2_password_auth
    pkt = _roundtrip(conn, data)
  File "/Users/apple/anaconda3/lib/python3.6/site-packages/pymysql/_auth.py", line 122, in _roundtrip
    pkt = conn._read_packet()
  File "/Users/apple/anaconda3/lib/python3.6/site-packages/pymysql/connections.py", line 684, in _read_packet
    packet.check_error()
  File "/Users/apple/anaconda3/lib/python3.6/site-packages/pymysql/protocol.py", line 220, in check_error
    err.raise_mysql_exception(self._data)
  File "/Users/apple/anaconda3/lib/python3.6/site-packages/pymysql/err.py", line 109, in raise_mysql_exception
    raise errorclass(errno, errval)
pymysql.err.OperationalError: (1045, "Access denied for user 'root'@'localhost' (using password: YES)")
2019-06-26 14:15:14 - ERROR - bin.app[line:48]: (1045, "Access denied for user 'root'@'localhost' (using password: YES)")
Traceback (most recent call last):
  File "/Users/apple/Desktop/pollution_statistic_forecast_app-develop_lstm/bin/app.py", line 40, in correlation
    data = build_samples.build_data_frame_for_correlation_analysis(data['starttime'], data['endtime'])
  File "/Users/apple/Desktop/pollution_statistic_forecast_app-develop_lstm/mods/build_samples.py", line 32, in build_data_frame_for_correlation_analysis
    data = pull_data_from_db(db_config, start_time, end_time)
  File "/Users/apple/Desktop/pollution_statistic_forecast_app-develop_lstm/mods/pull_data_from_db.py", line 25, in pull_data_from_db
    db = db_config['db'])                # name of the database
  File "/Users/apple/anaconda3/lib/python3.6/site-packages/pymysql/__init__.py", line 94, in Connect
    return Connection(*args, **kwargs)
  File "/Users/apple/anaconda3/lib/python3.6/site-packages/pymysql/connections.py", line 325, in __init__
    self.connect()
  File "/Users/apple/anaconda3/lib/python3.6/site-packages/pymysql/connections.py", line 599, in connect
    self._request_authentication()
  File "/Users/apple/anaconda3/lib/python3.6/site-packages/pymysql/connections.py", line 882, in _request_authentication
    auth_packet = _auth.caching_sha2_password_auth(self, auth_packet)
  File "/Users/apple/anaconda3/lib/python3.6/site-packages/pymysql/_auth.py", line 265, in caching_sha2_password_auth
    pkt = _roundtrip(conn, data)
  File "/Users/apple/anaconda3/lib/python3.6/site-packages/pymysql/_auth.py", line 122, in _roundtrip
    pkt = conn._read_packet()
  File "/Users/apple/anaconda3/lib/python3.6/site-packages/pymysql/connections.py", line 684, in _read_packet
    packet.check_error()
  File "/Users/apple/anaconda3/lib/python3.6/site-packages/pymysql/protocol.py", line 220, in check_error
    err.raise_mysql_exception(self._data)
  File "/Users/apple/anaconda3/lib/python3.6/site-packages/pymysql/err.py", line 109, in raise_mysql_exception
    raise errorclass(errno, errval)
pymysql.err.OperationalError: (1045, "Access denied for user 'root'@'localhost' (using password: YES)")
2019-06-26 14:25:50 - ERROR - bin.app[line:48]: (1045, "Access denied for user 'root'@'localhost' (using password: YES)")
Traceback (most recent call last):
  File "/Users/apple/Desktop/pollution_statistic_forecast_app-develop_lstm/bin/app.py", line 40, in correlation
    data = build_samples.build_data_frame_for_correlation_analysis(data['starttime'], data['endtime'])
  File "/Users/apple/Desktop/pollution_statistic_forecast_app-develop_lstm/mods/build_samples.py", line 32, in build_data_frame_for_correlation_analysis
    data = pull_data_from_db(db_config, start_time, end_time)
  File "/Users/apple/Desktop/pollution_statistic_forecast_app-develop_lstm/mods/pull_data_from_db.py", line 25, in pull_data_from_db
    db = db_config['db'])                # name of the database
  File "/Users/apple/anaconda3/lib/python3.6/site-packages/pymysql/__init__.py", line 94, in Connect
    return Connection(*args, **kwargs)
  File "/Users/apple/anaconda3/lib/python3.6/site-packages/pymysql/connections.py", line 325, in __init__
    self.connect()
  File "/Users/apple/anaconda3/lib/python3.6/site-packages/pymysql/connections.py", line 599, in connect
    self._request_authentication()
  File "/Users/apple/anaconda3/lib/python3.6/site-packages/pymysql/connections.py", line 882, in _request_authentication
    auth_packet = _auth.caching_sha2_password_auth(self, auth_packet)
  File "/Users/apple/anaconda3/lib/python3.6/site-packages/pymysql/_auth.py", line 265, in caching_sha2_password_auth
    pkt = _roundtrip(conn, data)
  File "/Users/apple/anaconda3/lib/python3.6/site-packages/pymysql/_auth.py", line 122, in _roundtrip
    pkt = conn._read_packet()
  File "/Users/apple/anaconda3/lib/python3.6/site-packages/pymysql/connections.py", line 684, in _read_packet
    packet.check_error()
  File "/Users/apple/anaconda3/lib/python3.6/site-packages/pymysql/protocol.py", line 220, in check_error
    err.raise_mysql_exception(self._data)
  File "/Users/apple/anaconda3/lib/python3.6/site-packages/pymysql/err.py", line 109, in raise_mysql_exception
    raise errorclass(errno, errval)
pymysql.err.OperationalError: (1045, "Access denied for user 'root'@'localhost' (using password: YES)")
2019-06-26 14:33:55 - ERROR - bin.app[line:48]: name 'data' is not defined
Traceback (most recent call last):
  File "/Users/apple/Desktop/pollution_statistic_forecast_app-develop_lstm/bin/app.py", line 42, in correlation
    samples = time_delayed_correlation()
  File "/Users/apple/Desktop/pollution_statistic_forecast_app-develop_lstm/mods/time_delayed_correlation_analysis.py", line 83, in time_delayed_correlation
    columns = list(data.columns)
NameError: name 'data' is not defined
2019-06-26 14:38:18 - INFO - bin.app[line:43]: time cost for correlation analysis: 24.60016393661499 secs
2019-06-26 14:39:12 - INFO - bin.app[line:43]: time cost for correlation analysis: 26.491065979003906 secs
2019-06-26 14:40:14 - INFO - bin.app[line:42]: time cost for correlation analysis: 22.625230073928833 secs
2019-06-26 14:42:59 - INFO - bin.app[line:42]: time cost for correlation analysis: 21.997573852539062 secs
2019-06-26 14:43:11 - INFO - bin.app[line:42]: time cost for correlation analysis: 20.134690046310425 secs
